Workbook

Sheet SS_Analysis
A1: Boost Conveter Design - Part I
A3: Boost Design Specifications
A5: Parameter | B5: Value | C5: Unit
A6: Max Vin(avg) | B6: 3.5 | C6: V
A7: Min Vin(avg) | B7: 2.5 | C7: V
A8: Nominal Vout(avg) | B8: 5 | C8: V
A9: Max Pout(avg) | B9: 5 | C9: W
A10: Min Pout(avg) | B10: 0.5 | C10: W
A11: Operating fs | B11: 100 | C11: kHz
A14: Evaluating Key Inductor Parameters for CCM (Theoretical)
A16: Parameter | B16: Value | C16: Unit (eq)
A17: Max Operating D | B17: =1-(B7/B8) -> 0.5 | C17: (1-1)
A18: Min Operating D | B18: =1-(B6/B9) -> 0.3 | C18: (1-2)
A19: Max IL(avg) = Iin(avg) | B19: =B9/B7 -> 2 | C19: A (1-3)
A20: Min IL(avg) = Iin(avg) | B20: =B10/B6 -> 0.14285714 | C20: A (1-4)
A21: D for Max L for CCM | B21: =1/3 -> 0.33333333 | C21: (1-5)
A22: Rload-crit | B22: =B8^2/B10 -> 50 | C22: Ω
A23: Min L for CCM | B23: =10^6*B22*B21*(1-B21)^2/(2*B11*10^3) -> 37.037037 | C23: µH (1-6)
A24: Min L with 20% margin | B24: =B23*1.2 -> 44.444444 | C24: µH
A25: Selected L | B25: 47 | C25: µH
A28: Evaluating Output Capacitor (Theoretical)
A30: Parameter | B30: Value | C30: Unit (eq)
A31: Max Vo Ripple | B31: 0.05 | C31: V
A32: Max Iout | B32: =B9/B8 -> 1 | C32: A
A33: Min Co | B33: =10^6*B32*B17/(B11*10^3*B31) -> 100 | C33: µF (1-7)
A34: Min Co with 20% margin | B34: =B33*1.2 -> 120 | C34: µF
A35: Selected Co | B35: 560 | C35: µF
A38: Evaluating Steady-State Operating Conditions (Theoretical)
A40: Parameter | B40: Value | C40: Unit (eq) | D40: Value | E40: Unit (eq) | F40: Value | G40: Unit (eq) | H40: Value | I40: Unit (eq) | J40: Value | K40: Unit (eq)
A41: Vout | B41: 5 | C41: V | D41: 5 | E41: V | F41: 5 | G41: V | H41: 5 | I41: V | J41: 5 | K41: V
A42: Vin | B42: 2.5 | C42: V | D42: 3.5 | E42: V | F42: 2.5 | G42: V | H42: 3.5 | I42: V | J42: 3 | K42: V
A43: Pout | B43: =B10 -> 0.5 | C43: W | D43: 0.5 | E43: W | F43: 5 | G43: W | H43: 5 | I43: W | J43: 2.75 | K43: W
A44: RLoad | B44: =B41^2/B43 -> 50 | C44: Ohms (1-8) | D44: =D41^2/D43 -> 50 | E44: Ohms (1-8) | F44: =F41^2/F43 -> 5 | G44: Ohms (1-8) | H44: =H41^2/H43 -> 5 | I44: Ohms (1-8) | J44: =J41^2/J43 -> 9.0909091 | K44: Ohms (1-8)
A45: Operating D | B45: =1-(B42/B41) -> 0.5 | C45: (1-9) | D45: =1-(D42/D41) -> 0.3 | E45: (1-9) | F45: =1-(F42/F41) -> 0.5 | G45: (1-9) | H45: =1-(H42/H41) -> 0.3 | I45: (1-9) | J45: =1-(J42/J41) -> 0.4 | K45: (1-9)
A46: Iin(avg) = IL(avg) | B46: =B43/B42 -> 0.2 | C46: A (1-10) | D46: =D43/D42 -> 0.14285714 | E46: A (1-10) | F46: =F43/F42 -> 2 | G46: A (1-10) | H46: =H43/H42 -> 1.4285714 | I46: A (1-10) | J46: =J43/J42 -> 0.91666667 | K46: A (1-10)
A47: dIL | B47: =B42*B45/($B$25*10^-6*$B$11*10^3) -> 0.26595745 | C47: A (1-11) | D47: =D42*D45/($B$25*10^-6*$B$11*10^3) -> 0.22340426 | E47: A (1-11) | F47: =F42*F45/($B$25*10^-6*$B$11*10^3) -> 0.26595745 | G47: A (1-11) | H47: =H42*H45/($B$25*10^-6*$B$11*10^3) -> 0.22340426 | I47: A (1-11) | J47: =J42*J45/($B$25*10^-6*$B$11*10^3) -> 0.25531915 | K47: A (1-11)
A48: DCM Achieved | B48: =IF(B46>=B47/2,"Yes","No") -> Yes | D48: =IF(D46>=D47/2,"Yes","No") -> Yes | F48: =IF(F46>=F47/2,"Yes","No") -> Yes | H48: =IF(H46>=H47/2,"Yes","No") -> Yes | J48: =IF(J46>=J47/2,"Yes","No") -> Yes
A49: Iin(pk) = IL(pk) | B49: =B46+(B47/2) -> 0.33297872 | C49: A (1-12) | D49: =D46+(D47/2) -> 0.25455927 | E49: A (1-12) | F49: =F46+(F47/2) -> 2.1329787 | G49: A (1-12) | H49: =H46+(H47/2) -> 1.5402736 | I49: A (1-12) | J49: =J46+(J47/2) -> 1.0443262 | K49: A (1-12)
A50: Iin(min) = IL(min) | B50: =B46-(B47/2) -> 0.067021277 | C50: A | D50: =D46-(D47/2) -> 0.031155015 | E50: A | F50: =F46-(F47/2) -> 1.8670213 | G50: A | H50: =H46-(H47/2) -> 1.3168693 | I50: A | J50: =J46-(J47/2) -> 0.78900709 | K50: A
A51: Iin(rms) = IL(rms) | B51: =SQRT(B46^2 + (B47^2/12)) -> 0.21422989 | C51: A (1-13) | D51: =SQRT(D46^2 + (D47^2/12)) -> 0.15673955 | E51: A (1-13) | F51: =SQRT(F46^2 + (F47^2/12)) -> 2.0014731 | G51: A (1-13) | H51: =SQRT(H46^2 + (H47^2/12)) -> 1.4300264 | I51: A (1-13) | J51: =SQRT(J46^2 + (J47^2/12)) -> 0.91962498 | K51: A (1-13)
...

Sheet Inductor_Design
A1: Inductor Design - Part II
A3: Transformer Design Specifications
A5: Parameter | B5: Value | C5: Unit
A6: Selected L | B6: =SS_Analysis!B25 -> 47 | C6: µH
A7: Max IL(avg) | B7: =SS_Analysis!F46 -> 2 | C7: A
A8: Max IL(pk) | B8: =SS_Analysis!F49 -> 2.1329787 | C8: A
A9: Max RMS IL | B9: =SS_Analysis!F51 -> 2.0014731 | C9: A
A10: Max Bmax | B10: 0.25 | C10: T
A11: Operating fs | B11: =SS_Analysis!B11 -> 100 | C11: kHz
A14: Core, Former & Magnet Wire Details
A16: Parameter | B16: Value | C16: Unit
A17: Core type | B17: EFD20
A18: Core material | B18: N97
A19: Ae | B19: 31 | C19: mm^2
A20: le | B20: 47 | C20: mm
A21: Ve | B21: 1460 | C21: mm^3
A22: AN | B22: 28.1 | C22: mm^2
A23: ln | B23: 40.2 | C23: mm
A24: Wire ρ | B24: =1.724*10^-8 -> 1.724e-08 | C24: Ωm
A25: µ0 | B25: =4*PI()*10^-7 -> 1.2566371e-06 | C25: H/m
A26: µe | B26: 1510
A27: Achievable Kf | B27: 0.65
A30: Evaluating Inductor Parameters
A32: Parameter | B32: Value | C32: Unit (eq)
A33: Selected lg | B33: 0.1 | C33: mm
A34: Inductor turns (N) | B34: =ROUND(SQRT((2*B6*10^-6*B33*10^-3)/(B25*B19*10^-6)),0) -> 16 | C34: Turns (1-1)
A35: Bmax | B35: =B34*B8*B25/(2*B33*10^-3) -> 0.21443041 | C35: T (1-2)
A36: Bmax < Max Bmax | B36: =IF(B35<=B10,"Yes","No") -> Yes
A37: Skin Depth | B37: =10^3*SQRT(B24/(PI()*B25*B11*10^3)) -> 0.20897232 | C37: mm (1-3)
A38: Selected Wire Diameter | B38: 0.5 | C38: mm
A39: Wire Acu | B39: =PI()*B38^2/4 -> 0.19634954 | C39: mm^2 (1-4)
A40: Parallel Wires (Np) | B40: 5
A41: Rdc of Inductor | B41: =10^3*B24*B34*B23*10^-3/(B40*B39*10^-6) -> 11.294926 | C41: mOhms (1-5)
A42: Max Rdc Loss in Lp | B42: =B9^2*B41*10^-3 -> 0.045246283 | C42: W (1-6)
A43: Bac | B43: =B35*10^3*SS_Analysis!F47/(2*B8) -> 13.368479 | C43: mT
A44: Hysteresis loss (Pv) | B44: =1.71*10^-5*B11^1.12*B43^2.29 -> 1.1264811 | C44: kW/m^3 (1-7)
A45: Total loss (Ploss) | B45: =(B44*10^3*B21*10^-9) + B42 -> 0.046890945 | C45: W (1-8)
A46: Jmax | B46: =B9/(B40*B39) -> 2.0386837 | C46: A/mm^2 (1-9)
A47: Total conductor area | B47: =B34*B40*B39/B27 -> 24.166097 | C47: mm^2
A49: Experimental Results
...

Sheet Testing_Openloop
B2: Testing with breadboard: E12 values
B3: Rl values | D3: Rl_E12 values | G3: Testing Items for each: | K3: Order list: breadboard testing
B4: 5 | C4: * | D4: 5.6 | E4: * | G4: Output V | K4: Breadboard
B5: 10 | C5: * | D5: 10 | E5: * | G5: Current through inductor | K5: 5.6, 10, 22, 33, 47 ohm resistors
B6: 15 | C6: * | D6: 15 | G6: Current through shunt branch | K6: 47uH inductor
B7: 20 | D7: 22 | E7: * | K7: Schotty diode
B8: 25 | C8: * | D8: 27 | G8: ^Note: Others were not measured
B9: 30 | C9: * | D9: 33 | G9: due to time constraints, and lack of | K9: > Input V given by DC power supply
B10: 35 | D10: 33 | E10: * | G10: 0.1ohm shunt resistors available. | K10: >Switch operated using oscilloscope
B11: 40 | C11: * | D11: 39
B12: 45 | C12: * | D12: 47
B13: 50 | C13: * | D13: 47 | E13: *
B15: Rl = 5.6 | C15: Real R: 5.58 | G15: Rl = 10 | H15: Real R: 10.07 | L15: Rl = 22 | M15: Real R: 22.08 | Q15: Rl = 33 | R15: Real R: 32.89 | V15: Rl = 47 | W15: Real R: 47.13
B16: Input V | C16: 2.5 | D16: 3 | E16: 3.5 | G16: Input V | H16: 2.5 | I16: 3 | J16: 3.5 | L16: Input V | M16: 2.5 | N16: 3 | O16: 3.5 | Q16: Input V | R16: 2.5 | S16: 3 | T16: 3.5 | V16: Input V | W16: 2.5 | X16: 3 | Y16: 3.5
B17: Duty Cycle | C17: 0.5 | D17: 0.4 | E17: 0.3 | G17: Duty Cycle | H17: 0.5 | I17: 0.4 | J17: 0.3 | L17: Duty Cycle | M17: 0.5 | N17: 0.4 | O17: 0.3 | Q17: Duty Cycle | R17: 0.5 | S17: 0.4 | T17: 0.3 | V17: Duty Cycle | W17: 0.5 | X17: 0.4 | Y17: 0.3
B18: Output V | C18: 3V | D18: 3.3 | E18: 3.55 | G18: Output V | H18: 3.5V | I18: 3.8V | J18: 3.9V | L18: Output V | M18: 3.4V | N18: 3.9V | O18: 4V | Q18: Output V | R18: 4V | S18: 4.1V | T18: 4.2V | V18: Output V | W18: 4.2V | X18: 4.26V | Y18: 4.3V
B22: Testing on PCB in Open Loop (Ideal Conditions)
B24: Rl = 5 | G24: Rl = 10 | L24: Rl = 20 | Q24: Rl = 30 | V24: Rl = 40 | AA24: Rl = 50
B25: Input V | C25: 2.5 | D25: 3 | E25: 3.5 | G25: Input V | H25: 2.5 | I25: 3 | J25: 3.5 | L25: Input V | M25: 2.5 | N25: 3 | O25: 3.5 | Q25: Input V | R25: 2.5 | S25: 3 | T25: 3.5 | V25: Input V | W25: 2.5 | X25: 3 | Y25: 3.5 | AA25: Input V | AB25: 2.5 | AC25: 3 | AD25: 3.5
B26: Duty Cycle | C26: 0.5 | D26: 0.4 | E26: 0.3 | G26: Duty Cycle | H26: 0.5 | I26: 0.4 | J26: 0.3 | L26: Duty Cycle | M26: 0.5 | N26: 0.4 | O26: 0.3 | Q26: Duty Cycle | R26: 0.5 | S26: 0.4 | T26: 0.3 | V26: Duty Cycle | W26: 0.5 | X26: 0.4 | Y26: 0.3 | AA26: Duty Cycle | AB26: 0.5 | AC26: 0.4 | AD26: 0.3
B27: Output V | C27: 3.73 | D27: 3.95 | E27: 4.11 | G27: Output V | H27: 4.09 | I27: 4.22 | J27: 4.3 | L27: Output V | M27: 4.28 | N27: 4.38 | O27: 4.45 | Q27: Output V | R27: 4.38 | S27: 4.45 | T27: 4.51 | V27: Output V | W27: 4.42 | X27: 4.49 | Y27: 4.53 | AA27: Output V | AB27: 4.47 | AC27: 4.5 | AD27: 4.55
B28: MCU_VFB | C28: =C27/2 -> 1.865 | D28: =D27/2 -> 1.975 | E28: =E27/2 -> 2.055 | G28: MCU_VFB | H28: =H27/2 -> 2.045 | I28: =I27/2 -> 2.11 | J28: =J27/2 -> 2.15 | L28: MCU_VFB | M28: =M27/2 -> 2.14 | N28: =N27/2 -> 2.19 | O28: =O27/2 -> 2.225 | Q28: MCU_VFB | R28: =R27/2 -> 2.19 | S28: =S27/2 -> 2.225 | T28: =T27/2 -> 2.255 | V28: MCU_VFB | W28: =W27/2 -> 2.21 | X28: =X27/2 -> 2.245 | Y28: =Y27/2 -> 2.265 | AA28: MCU_VFB | AB28: =AB27/2 -> 2.235 | AC28: =AC27/2 -> 2.25 | AD28: =AD27/2 -> 2.275
B30: >Testing duty cycle that gives Vout = 5V (less test cases) | P30: Output Voltages as displayed on Oscilloscope - (At boundary conditions - 2.5/3.5V, 5/50ohm)
B32: Rl = 5 | F32: Rl = 50 | J32: *Overvoltage limits voltage to 5.99V at 3.5V Vin
B33: Input V | C33: 2.5 | D33: 3.5 | F33: Input V | G33: 2.5 | H33: 3.5 | J33: At, 65% duty cycle it starts to limit
B34: Duty Cycle | C34: 1 - 0.35 | D34: 1 - 0.6 | F34: Duty Cycle | G34: 1 - 0.47 | H34: 1 - 0.67 | J34: *Overvoltage limits voltage to 5.97V at 2.5V Vin
B35: Output V | C35: 5.04 | D35: 5.05 | F35: Output V | G35: 4.97 | H35: 4.98 | J35: At 65% duty cycle it starts to limit
B36: Efficiency | C36: =(C38/C37) -> 0.6832 | D36: =D38/D37 -> 0.78988327 | F36: Efficiency | G36: =G38/G37 -> 0.86 | H36: =H38/H37 -> 0.86
B37: Pin | C37: 6.25 | D37: 5.14 | F37: Pin | G37: 0.5 | H37: 0.5 | J37: *Overvoltage cannot occur at 5ohms since
B38: Pout | C38: 4.27 | D38: 4.06 | F38: Pout | G38: 0.43 | H38: 0.43 | J38: current is limited to 3A
B39: V ripple | C39: 3.9 | D39: 4.04 | F39: V ripple | G39: 2.88 | H39: 2.56
A54: C2
A56: C1
B59: Current feedback testing - (IFB is input, IFBF is output) | J59: Voltage divider check: | P59: Current sense input & output values as displayed on Oscilloscope
B61: Rl = 5 | F61: Rl = 50 | J61: Rl = 5
B62: Input V | C62: 2.5 | D62: 3.5 | F62: Input V | G62: 2.5 | H62: 3.5 | J62: Input V | K62: 2.5
B63: Duty Cycle | C63: 0.5 | D63: 0.3 | F63: Duty Cycle | G63: 0.5 | H63: 0.3 | J63: Duty cycle | K63: 0.5
B64: IFB(mean) (mV) | C64: 73 | D64: 35.7 | F64: IFB(mean) (mV) | G64: 8.8 | H64: 3.9 | J64: VFB(mean) (V) | K64: 1.85
B65: IFB(peak) (mV) | C65: 612 | D65: 592.9 | F65: IFB(peak) (mV) | G65: 250 | H65: 231.3 | J65: VFB(pk-pk amplitude) (V) | K65: 0.42
B66: IFBF(mean) (mV) | C66: 277.9 | D66: 131.4 | F66: IFBF(mean) (mV) | G66: 39.6 | H66: 19.8 | J66: VFBF(mean) (V) | K66: 3.66
...

Sheet Testing_Closedloop
B4: 2.5V Vin Results | O4: 3.5V Vin Results
B5: Rl | C5: 5 | D5: 10 | E5: 50 | O5: Rl | P5: 5 | Q5: 10 | R5: 50
B6: Output V | C6: 4.795 | D6: 5.163 | E6: 5.194 | O6: Output V | P6: 5.163 | Q6: 5.161 | R6: 5.19
B7: Efficiency | C7: =C9/C8 -> 0.63833076 | D7: =D9/D8 -> 0.78412698 | E7: =E9/E8 -> 0.89473684 | O7: Efficiency | P7: =P9/P8 -> 0.76984127 | Q7: =Q9/Q8 -> 0.85121107 | R7: =R9/R8 -> 0.90909091
B8: Pin | C8: 6.47 | D8: 3.15 | E8: 0.57 | O8: Pin | P8: 6.3 | Q8: 2.89 | R8: 0.55
B9: Pout | C9: 4.13 | D9: 2.47 | E9: 0.51 | O9: Pout | P9: 4.85 | Q9: 2.46 | R9: 0.5
B10: V ripple (mV) | C10: 240 | D10: 119 | E10: 51 | O10: V ripple (mV) | P10: 141 | Q10: 89 | R10: 56
B11: Trise (ms) | C11: 118.5 | D11: 28.4 | E11: 20.8 | O11: Trise (ms) | P11: 30.1 | Q11: 14.9 | R11: 15.5
